Workbook

Sheet Instructivo 
B2: INSTRUCTIVO DE USO
B4: Contenido
B5: Este archivo está compuesto por tres pestañas las cuales encontraremos en la parte inferior izquierda del documento:
B6: 1. Instructivo
B7: 2. Lista de Verificación
B8: 3. Reporte de Evaluación
B10: Llenado de la lista de Verificación
B11: En la lista de verificación nos encontramos con las siguientes columnas:
B47: Llenado del Reporte de Evaluación

Sheet Lista de Verificación
A1: Familia | B1: Indicador | C1: TIPO | D1: CÓDIGO | E1: INDICADORES | F1: Aplica (Si-No) | G1: NO cumple | H1: SI cumple | I1: Observaciones (¿porqué no aplica?) | J1: Evidencias de cumplimiento
A2: 1 | B2: 1 | C2: P | D2: =CONCATENATE(A2,".",B2,".",C2) -> 1.1.P | E2: ¿El establecimiento cuenta con elementos promocionales de turismo de salud en inglés en su página de internet? | F2: SI | H2: X | J2: Capturas de pantalla de la página web, el botón de traducción y los servicios de salud y bienestar que ofrece la empresa.
A3: 1 | B3: 2 | C3: P | D3: =CONCATENATE(A3,".",B3,".",C3) -> 1.2.P | E3: ¿El establecimiento cuenta con presencia en redes sociales con información de turismo de salud? | F3: SI | H3: X | J3: Capturas de pantalla de las publicaciones de salud y bienestar de la empresa en redes sociales.
A4: 1 | B4: 3 | C4: P | D4: =CONCATENATE(A4,".",B4,".",C4) -> 1.3.P | E4: ¿El establecimiento cuenta con sinergias comerciales con hospitales, clínicas, spas, centros de relajación, centros de retiro, etc., relacionadas con el turismo de salud? | F4: SI | H4: X | J4: Evidencia de cada sinergia la cual incluye foto del lugar, dirección, página de Facebook, fotos de convenios firmados, catálogos de servicios y precios
A5: 1 | B5: 4 | C5: P | D5: =CONCATENATE(A5,".",B5,".",C5) -> 1.4.P | E5: ¿El establecimiento conoce a detalle la lista de empresas publicadas en “Visit Mexico” y los servicios de turismo de salud que ofrecen? | F5: SI | H5: X | J5: Capturas de pantalla de la página web de VisitMéxico, el chat con la asistencia virtual, y captura de la solicitud de registro en la página de VisitMéxico.
A6: 1 | B6: 5 | C6: C | D6: =CONCATENATE(A6,".",B6,".",C6) -> 1.5.C | E6: ¿El establecimiento cuenta con información de sitios turísticos de bienestar y relajación? | F6: SI | H6: X | J6: Fotografías como evidencia del lugar donde la empresa tiene la información de sitios turísticos de salud y bienestar.
A7: 1 | B7: 6 | C7: C | D7: =CONCATENATE(A7,".",B7,".",C7) -> 1.6.C | E7: ¿El establecimiento participa en sitios de referencia turística? | F7: SI | H7: X | J7: Capturas de pantalla de los diferentes portales de reservación en los que tiene presencia la empresa, así como su respectivo enlace.
A8: 1 | B8: 7 | C8: P | D8: =CONCATENATE(A8,".",B8,".",C8) -> 1.7.P | E8: ¿El establecimiento cuenta con alguna sinergia comprobable en el extranjero para captación de pacientes? | F8: SI | H8: X | J8: Capturas de pantalla y fotografías de los convenios firmados y pagina de cada una de las sinergias.
A9: 2 | B9: 1 | C9: P | D9: =CONCATENATE(A9,".",B9,".",C9) -> 2.1.P | E9: ¿El Establecimiento cuenta con habitaciones especiales para recuperación del paciente? | F9: SI | H9: X | J9: Fotografías de las habitaciones con las que cuenta la empresa de acuerdo con las necesidades de un paciente en recuperación.
A10: 2 | B10: 2 | C10: C | D10: =CONCATENATE(A10,".",B10,".",C10) -> 2.2.C | E10: ¿El establecimiento cuenta con paquetes especiales en habitaciones para familiares de pacientes? | F10: SI | H10: X | J10: Evidencia fotográfica de paquete especial, el cual se encuentra de forma impresa en la recepción y el lobby de la empresa.
A11: 2 | B11: 3 | C11: C | D11: =CONCATENATE(A11,".",B11,".",C11) -> 2.3.C | E11: ¿El establecimiento cuenta con habitaciones comunicadas para paciente y familiares? | F11: SI | H11: X | J11: Evidencia fotográfica de las habitaciones comunicadas.
A12: 2 | B12: 4 | C12: C | D12: =CONCATENATE(A12,".",B12,".",C12) -> 2.4.C | E12: ¿El establecimiento cuenta con instalaciones y servicios de spa? | F12: SI | H12: X | J12: Evidencia fotográfica del lugar, así como capturas de sus catálogos de servicios y precios, así fotografías de la sinergia firmada.
A13: 2 | B13: 5 | C13: C | D13: =CONCATENATE(A13,".",B13,".",C13) -> 2.5.C | E13: ¿El establecimiento cuenta con tina de hidromasaje? | F13: SI | H13: X | J13: Evidencia fotográfica de la tina de hidromasaje con la que cuenta la sinergia de la empresa, y fotografía de la sinergia firmada.
... A18: 3 | B18: 1 | C18: P | D18: =CONCATENATE(A18,".",B18,".",C18) -> 3.1.P | E18: ¿El establecimiento cuenta con un catálogo de precios de servicios de salud actualizado (médicos y de bienestar)? | F18: SI | H18: X | J18: Evidencia fotográfica y capturas de los catálogos de servicios y precios de las sinergias, así como la promoción especial propia de la empresa.
A19: 3 | B19: 2 | C19: P | D19: =CONCATENATE(A19,".",B19,".",C19) -> 3.2.P | E19: ¿El establecimiento cuenta con un catálogo de servicios de salud certificados (médicos y de bienestar)? | F19: NO | I19: No aplica por ser HOTEL | J19: NO APLICA POR SER HOTEL
A20: 3 | B20: 3 | C20: P | D20: =CONCATENATE(A20,".",B20,".",C20) -> 3.3.P | E20: ¿El establecimiento cuenta con certificaciones y/o acreditaciones médicas nacionales? | F20: NO | I20: No aplica por ser HOTEL | J20: NO APLICA POR SER HOTEL
A21: 3 | B21: 4 | C21: C | D21: =CONCATENATE(A21,".",B21,".",C21) -> 3.4.C | E21: ¿El establecimiento cuenta con certificaciones y/o acreditaciones médicas internacionales? (Joint Commission International) | F21: NO | I21: No aplica por ser HOTEL | J21: NO APLICA POR SER HOTEL
A22: 3 | B22: 5 | C22: P | D22: =CONCATENATE(A22,".",B22,".",C22) -> 3.5.P | E22: ¿El catálogo de servicios está impreso en inglés y describe los costos de los servicios con cargo extra explícitamente señalados, así como indicando definición del servicio, horario de las prestaciones y en el caso que éstos sean proporcionados por terceros, lugar o teléfono donde se pueden contratar? | F22: SI | H22: X | J22: Evidencia fotográfica de los catálogos promocionales en inglés de la empresa y de las sinergias con las que cuenta la empresa.
A23: 3 | B23: 6 | C23: P | D23: =CONCATENATE(A23,".",B23,".",C23) -> 3.6.P | E23: ¿Los artículos y precios de los productos o servicios se presentan en dólares y/o pesos? | F23: SI | H23: X | J23: Capturas de pantalla del promocional de la empresa con los precios en dólares, así como el de la sinergia Terapia Móvil
A24: 3 | B24: 7 | C24: P | D24: =CONCATENATE(A24,".",B24,".",C24) -> 3.7.P | E24: ¿Se hace del conocimiento del turista de salud el tipo de cambio a la fecha pesos-dólares? | F24: SI | H24: X | J24: Evidencia fotográfica del tipo de cambio que se encuentra en la recepción y captura de pantalla de la página del diario oficial de la federación donde se ve publicado el tipo de cambio del día.
A25: 3 | B25: 8 | C25: P | D25: =CONCATENATE(A25,".",B25,".",C25) -> 3.8.P | E25: ¿Se le informa al turista de salud, en inglés, las políticas de servicio y de cobro antes de prestar el servicio? | F25: SI | H25: X | J25: Capturas de pantalla de como arroja el sistema los registros en inglés y en español, así como documentos de las sinergias donde muestra sus políticas en inglés.
A26: 4 | B26: 1 | C26: C | D26: =CONCATENATE(A26,".",B26,".",C26) -> 4.1.C | E26: ¿El establecimiento cuenta con distintivos H y/o Punto Limpio? | F26: SI | H26: X | J26: Evidencia fotográfica de los distintivos, así como del lugar al que corresponde el distintivo.
A27: 4 | B27: 2 | C27: C | D27: =CONCATENATE(A27,".",B27,".",C27) -> 4.2.C | E27: ¿El establecimiento cuenta con menú de alimentación saludable, diseñado por expertos? | F27: SI | H27: X | J27: Evidencia fotográfica del menú saludable y la documentación del experto.
A28: 4 | B28: 3 | C28: P | D28: =CONCATENATE(A28,".",B28,".",C28) -> 4.3.P | E28: ¿El personal está capacitado en la terminología médica utilizada en turismo de salud, tanto en inglés como en español? | F28: SI | H28: X | J28: Evidencia fotográfica de cada uno de los curos en las dos fechas indicadas, captura de pantalla de la convocatoria a la capacitación, foto de la lista de asistencia, y foto de los diplomas obtenidos por el personal de la empresa.
A29: 4 | B29: 4 | C29: P | D29: =CONCATENATE(A29,".",B29,".",C29) -> 4.4.P | E29: ¿El establecimiento cuenta con convenios con empresas de servicio de ambulancia? | F29: SI | H29: X | J29: Evidencia fotográfica del convenio firmado.
A30: 4 | B30: 5 | C30: C | D30: =CONCATENATE(A30,".",B30,".",C30) -> 4.5.C | E30: ¿El establecimiento cuenta con personal capacitado para dar atención al paciente en recuperación? | F30: SI | H30: X | J30: Evidencia fotográfica de la capacitación del personal de la empresa, así como fotos de los documentos y certificaciones del personal certificado de las sinergias.
A31: 4 | B31: 6 | C31: C | D31: =CONCATENATE(A31,".",B31,".",C31) -> 4.6.C | E31: ¿El establecimiento pertenece o está vinculado a alguna asociación o clúster de turismo de salud? | F31: SI | H31: X | J31: Capturas de pantalla del pago realizado a las asociaciones, así como la factura y las constancias de casa asociación.
A32: 4 | B32: 7 | C32: P | D32: =CONCATENATE(A32,".",B32,".",C32) -> 4.7.P | E32: ¿El personal médico que atiende al turista de salud domina el idioma inglés? | F32: SI | H32: X | J32: Evidencia con fotografías y documentos escaneados de los certificados del personal que labora en la sinergia
A33: 4 | B33: 8 | C33: P | D33: =CONCATENATE(A33,".",B33,".",C33) -> 4.8.P | E33: ¿Se cuenta con personal de atención que hable inglés, ya sea interno o externo, para prestar asistencia y asesoría al turista de salud durante su estancia? | F33: SI | H33: X | J33: Evidencia fotográfica de certificado TOEFL de la recepcionista de la empresa, así como fotos de los certificados entregados al personal de la empresa que asistió a la captación del idioma inglés en terminología médica.
... A40: 5 | B40: 4 | C40: C | D40: =CONCATENATE(A40,".",B40,".",C40) -> 5.4.C | E40: ¿Los empleados de contacto con el cliente toman cursos de inglés y de atención al cliente al menos 2 veces al año? | F40: SI | H40: X | J40: Evidencia fotográfica de las capacitaciones impartidas al personal de la empresa.
E43: Cálculo de Resultados | F43: Indicadores | G43: Puntos | H43: Distribución
E44: Total de indicadores obligatorios que aplican | F44: =COUNTIFS(C2:C40,"P", F2:F40, "SI") -> 21 | G44: =F44*2 -> 42 | H44: =G44/G46 -> 0.73684211
E45: Total de indicadores deseables que aplican | F45: =COUNTIFS(C2:C40,"C", F2:F40,"SI") -> 15 | G45: =F45*1 -> 15 | H45: =G45/G46 -> 0.26315789
E46: Total de puntos que aplican | G46: =G44+G45 -> 57
E48: Total de indicadores obligatorios que aplican y se cumplieron | F48: =COUNTIFS(C2:C40,"P", F2:F40, "SI", H2:H40, "X") -> 21 | G48: =F48*2 -> 42 | H48: =G48/G50 -> 0.73684211
E49: Total de indicadores deseables que aplican y se cumplieron | F49: =COUNTIFS(C2:C40,"C", F2:F40, "SI", H2:H40, "X") -> 15 | G49: =F49*1 -> 15 | H49: =G49/G50 -> 0.26315789
E50: Total de puntos que aplican y se cumplieron | G50: =G48+G49 -> 57
E52: PORCENTAJE DE CUMPLIMIENTO | G52: =G50/G46 -> 1
E54: =IF(G52<0.85, "La organización no cuenta con el puntaje mínimo para obtener este Sello. Favor de ponerse en contacto con un consultor acreditado por SECTUR para solicitar la asesoría necesaria para la obtención del Sello.", "La organización supera el puntaje mínimo por lo que es candidata a obtener éste Sello. Favor de ponerse en contacto con un consultor acreditado por SECTUR para solicitar validación de evidencias.") -> La organización supera el puntaje mínimo por lo que es candidata a obtener éste Sello. Favor de ponerse en contacto con un consultor acreditado por SECTUR para solicitar validación de evidencias.

Sheet REPORTE DE EVALUACIÓN
B2: MSE: TURISMO DE SALUD
B5: Empresa: HOTEL EMILY. OPERADORA DE NEGOCIOS RORE S. DE R.L. DE C.V. | C5: Consultor: | D5: CYNTHIA ERICKA GARCIA DIAZ
B6: □ Incicial X. Final Fecha de aplicación: | C6: 22 DE JUNIO 2026
B9: Reporte de Evaluación
B11: Cálculo de Resultados | C11: Indicadores | D11: Puntos | E11: Distribución
B12: Total de indicadores prioritarios que aplican | C12: =COUNTIFS('Lista de Verificación'!C2:C40,"P",'Lista de Verificación'!F2:F40, "SI") -> 21 | D12: =C12*2 -> 42 | E12: =D12/D14 -> 0.73684211
B13: Total de indicadores complementarios que aplican | C13: =COUNTIFS('Lista de Verificación'!C2:C40,"C",'Lista de Verificación'!F2:F40, "SI") -> 15 | D13: =C13*1 -> 15 | E13: =D13/D14 -> 0.26315789
B14: TOTAL DE PUNTOS QUE APLICAN | D14: =D12+D13 -> 57
B16: Total de indicadores prioritarios que aplican y se cumplieron | C16: =COUNTIFS('Lista de Verificación'!C2:C40,"P",'Lista de Verificación'!F2:F40, "SI", 'Lista de Verificación'!H2:H40, "X") -> 21 | D16: =C16*2 -> 42 | E16: =D16/D18 -> 0.73684211
B17: Total de indicadores complementarios que aplican y se cumplieron | C17: =COUNTIFS('Lista de Verificación'!C2:C40,"C",'Lista de Verificación'!F2:F40, "SI", 'Lista de Verificación'!H2:H40, "X") -> 15 | D17: =C17*1 -> 15 | E17: =D17/D18 -> 0.26315789
B18: TOTAL DE PUNTOS QUE APLICAN Y SE CUMPLIERON | D18: =D16+D17 -> 57
B20: PORCENTAJE DE CUMPLIMIENTO GENERAL | D20: =D18/D14 -> 1 | E20: =IF(Table24[[#This Row],[Column3]]<0.85, "No Acredita", "Si Acredita") -> Si Acredita
B22: =IF(D20<0.85, "La organización no cuenta con el puntaje mínimo para obtener este Sello. Favor de ponerse en contacto con un consultor acreditado por SECTUR para solicitar la asesoría necesaria para la obtención del Sello.", "La organización supera el puntaje mínimo por lo que es candidata a obtener éste Sello. Favor de ponerse en contacto con un consultor acreditado por SECTUR para solicitar validación de evidencias.") -> La organización supera el puntaje mínimo por lo que es candidata a obtener éste Sello. Favor de ponerse en contacto con un consultor acreditado por SECTUR para solicitar validación de evidencias.
B25: Matriz de Clasificación de Indicadores
B27: Familias de Indicadores | C27: Total | D27: Prioritarios | E27: Complementarios
B28: 1.- Comunicación | C28: 7 | D28: 5 | E28: 2
B29: 2.- Instalaciones | C29: 9 | D29: 2 | E29: 7
B30: 3.- Transparencia | C30: 8 | D30: 7 | E30: 1
B31: 4.- Servicio | C31: 11 | D31: 6 | E31: 5
B32: 5.- Educación | C32: 4 | D32: 3 | E32: 1
B33: TOTAL | C33: =SUM(C28:C32) -> 39 | D33: =SUM(D28:D32) -> 23 | E33: =SUM(E28:E32) -> 16
B36: Resultados por familia de Indicadores
B39: =B28 -> 1.- Comunicación
C40: Indicadores | D40: Puntos | E40: Distribución
B41: Total de indicadores prioritarios que aplican | C41: =COUNTIFS('Lista de Verificación'!$A$2:$A$40, "1", 'Lista de Verificación'!$C$2:$C$40,"P",'Lista de Verificación'!$F$2:$F$40, "SI") -> 5 | D41: =C41*2 -> 10 | E41: =D41/D43 -> 0.83333333
B42: Total de indicadores complementarios que aplican | C42: =COUNTIFS('Lista de Verificación'!$A$2:$A$40, "1", 'Lista de Verificación'!$C$2:$C$40,"C",'Lista de Verificación'!$F$2:$F$40, "SI") -> 2 | D42: =C42*1 -> 2 | E42: =D42/D43 -> 0.16666667
B43: Total de puntos que aplican | D43: =D41+D42 -> 12
B45: Total de indicadores prioritarios que aplican y se cumplieron | C45: =COUNTIFS('Lista de Verificación'!$A$2:$A$40, "1",'Lista de Verificación'!$C$2:$C$40,"P",'Lista de Verificación'!$F$2:$F$40, "SI", 'Lista de Verificación'!$H$2:$H$40, "X") -> 5 | D45: =C45*2 -> 10 | E45: =D45/D47 -> 0.83333333
B46: Total de indicadores complementarios que aplican y se cumplieron | C46: =COUNTIFS('Lista de Verificación'!$A$2:$A$40, "1", 'Lista de Verificación'!$C$2:$C$40,"C",'Lista de Verificación'!$F$2:$F$40, "SI", 'Lista de Verificación'!$H$2:$H$40, "X") -> 2 | D46: =C46*1 -> 2 | E46: =D46/D47 -> 0.16666667
B47: Total de puntos que aplican y se cumplieron | D47: =D45+D46 -> 12
B49: PORCENTAJE DE CUMPLIMIENTO GENERAL | D49: =D47/D43 -> 1
B53: =B29 -> 2.- Instalaciones
C54: Indicadores | D54: Puntos | E54: Distribución
B55: Total de indicadores prioritarios que aplican | C55: =COUNTIFS('Lista de Verificación'!$A$2:$A$40, "2", 'Lista de Verificación'!$C$2:$C$40,"P",'Lista de Verificación'!$F$2:$F$40, "SI") -> 2 | D55: =C55*2 -> 4 | E55: =D55/D57 -> 0.36363636
B56: Total de indicadores complementarios que aplican | C56: =COUNTIFS('Lista de Verificación'!$A$2:$A$40, "2", 'Lista de Verificación'!$C$2:$C$40,"C",'Lista de Verificación'!$F$2:$F$40, "SI") -> 7 | D56: =C56*1 -> 7 | E56: =D56/D57 -> 0.63636364
B57: Total de puntos que aplican | D57: =D55+D56 -> 11
B59: Total de indicadores prioritarios que aplican y se cumplieron | C59: =COUNTIFS('Lista de Verificación'!$A$2:$A$40, "2",'Lista de Verificación'!$C$2:$C$40,"P",'Lista de Verificación'!$F$2:$F$40, "SI", 'Lista de Verificación'!$H$2:$H$40, "X") -> 2 | D59: =C59*2 -> 4 | E59: =D59/D61 -> 0.36363636
B60: Total de indicadores complementarios que aplican y se cumplieron | C60: =COUNTIFS('Lista de Verificación'!$A$2:$A$40, "2", 'Lista de Verificación'!$C$2:$C$40,"C",'Lista de Verificación'!$F$2:$F$40, "SI", 'Lista de Verificación'!$H$2:$H$40, "X") -> 7 | D60: =C60*1 -> 7 | E60: =D60/D61 -> 0.63636364
B61: Total de puntos que aplican y se cumplieron | D61: =D59+D60 -> 11
B63: PORCENTAJE DE CUMPLIMIENTO GENERAL | D63: =D61/D57 -> 1
...
